<?xml version="1.0" encoding="utf-8"?>
<robot name="ur10e_robot_mod_new">
  <material name="JointPlasticBlack">
    <color rgba="0.1038 0.1038 0.1038 1" />
  </material>
  <material name="JointPlasticBlue">
    <color rgba="0.2979 0.6108 0.797 1" />
  </material>
  <material name="JointPlasticGrey">
    <color rgba="0.4 0.4 0.4 1" />
  </material>
  <material name="Aluminum">
    <color rgba="0.6981 0.6981 0.6981 1" />
  </material>
  <link name="base">
    <visual>
      <origin rpy="0 0 -3.141593" />
      <geometry>
        <mesh filename="package://meshes/base.stl" scale="1 1 1" />
      </geometry>
      <material name="JointPlasticBlack">
        <color rgba="0.1038 0.1038 0.1038 1" />
      </material>
    </visual>
    <collision>
      <origin rpy="0 0 -3.141593" />
      <geometry>
        <mesh filename="package://meshes/base.stl" scale="1 1 1" />
      </geometry>
    </collision>
  </link>
  <link name="base_link">
    <inertial>
      <origin rpy="0 0 0" xyz="0 0 0" />
      <mass value="4" />
      <inertia ixx="0.00610633101314306" ixy="0" ixz="0" iyy="0.00610633101314306" iyz="0" izz="0.0112500004470348" />
    </inertial>
    <visual>
      <origin rpy="0 0 -3.141593" />
      <geometry>
        <mesh filename="package://meshes/base.stl" scale="1 1 1" />
      </geometry>
      <material name="JointPlasticBlack">
        <color rgba="0.1038 0.1038 0.1038 1" />
      </material>
    </visual>
    <collision>
      <origin rpy="0 0 -3.141593" />
      <geometry>
        <mesh filename="package://meshes/base.stl" scale="1 1 1" />
      </geometry>
    </collision>
  </link>
  <link name="shoulder_link">
    <inertial>
      <origin rpy="0 0 0" xyz="0 0 0" />
      <mass value="7.7779998779" />
      <inertia ixx="0.0314743109047413" ixy="0" ixz="0" iyy="0.0314743109047413" iyz="0" izz="0.0218756254762411" />
    </inertial>
    <visual>
      <origin rpy="0 0 -3.141593" />
      <geometry>
        <mesh filename="package://meshes/shoulder.stl" scale="1 1 1" />
      </geometry>
      <material name="JointPlasticBlack">
        <color rgba="0.1038 0.1038 0.1038 1" />
      </material>
    </visual>
    <collision>
      <origin rpy="0 0 -3.141593" />
      <geometry>
        <mesh filename="package://meshes/shoulder.stl" scale="1 1 1" />
      </geometry>
    </collision>
  </link>
  <link name="upper_arm_link">
    <inertial>
      <origin rpy="90 0 0" xyz="-0.306 0 0.175" />
      <mass value="12.9300003052" />
      <inertia ixx="0.036365631967783" ixy="0" ixz="5.17803222521707E-08" iyy="0.421753793954849" iyz="0" izz="0.421753913164139" />
    </inertial>
    <visual>
      <origin rpy="-4.712389 0 -1.570796" xyz="0 0 0.1762" />
      <geometry>
        <mesh filename="package://meshes/upperarm.stl" scale="1 1 1" />
      </geometry>
      <material name="JointPlasticBlue">
        <color rgba="0.2979 0.6108 0.797 1" />
      </material>
    </visual>
    <collision>
      <origin rpy="-4.712389 0 -1.570796" xyz="0 0 0.1762" />
      <geometry>
        <mesh filename="package://meshes/upperarm.stl" scale="1 1 1" />
      </geometry>
    </collision>
  </link>
  <link name="forearm_link">
    <inertial>
      <origin rpy="90 0 0" xyz="-0.285775 0 0.0393" />
      <mass value="3.8699998856" />
      <inertia ixx="0.0108843771740794" ixy="0" ixz="1.34236133320087E-08" iyy="0.110793024301529" iyz="0" izz="0.110793054103851" />
    </inertial>
    <visual>
      <origin rpy="-4.712389 0 -1.570796" xyz="0 0 0.0393" />
      <geometry>
        <mesh filename="package://meshes/forearm.stl" scale="1 1 1" />
      </geometry>
      <material name="JointPlasticGrey">
        <color rgba="0.4 0.4 0.4 1" />
      </material>
    </visual>
    <collision>
      <origin rpy="-4.712389 0 -1.570796" xyz="0 0 0.0393" />
      <geometry>
        <mesh filename="package://meshes/forearm.stl" scale="1 1 1" />
      </geometry>
    </collision>
  </link>
  <link name="wrist_1_link">
    <inertial>
      <origin rpy="0 0 0" xyz="0 0 0" />
      <mass value="1.9600000381" />
      <inertia ixx="0.00510824797675014" ixy="0" ixz="0" iyy="0.00510824797675014" iyz="0" izz="0.00551250018179417" />
    </inertial>
    <visual>
      <origin rpy="-4.712389 0 0" xyz="0 0 -0.135" />
      <geometry>
        <mesh filename="package://meshes/wrist1.stl" scale="1 1 1" />
      </geometry>
      <material name="JointPlasticBlue">
        <color rgba="0.2979 0.6108 0.797 1" />
      </material>
    </visual>
    <collision>
      <origin rpy="-4.712389 0 0" xyz="0 0 -0.135" />
      <geometry>
        <mesh filename="package://meshes/wrist1.stl" scale="1 1 1" />
      </geometry>
    </collision>
  </link>
  <link name="wrist_2_link">
    <inertial>
      <origin rpy="0 0 0" xyz="0 0 0" />
      <mass value="1.9600000381" />
      <inertia ixx="0.00510824797675014" ixy="0" ixz="0" iyy="0.00510824797675014" iyz="0" izz="0.00551250018179417" />
    </inertial>
    <visual>
      <origin xyz="0 0 -0.12" />
      <geometry>
        <mesh filename="package://meshes/wrist2.stl" scale="1 1 1" />
      </geometry>
      <material name="JointPlasticBlue">
        <color rgba="0.2979 0.6108 0.797 1" />
      </material>
    </visual>
    <collision>
      <origin xyz="0 0 -0.12" />
      <geometry>
        <mesh filename="package://meshes/wrist2.stl" scale="1 1 1" />
      </geometry>
    </collision>
  </link>
  <link name="wrist_3_link">
    <inertial>
      <origin rpy="0 0 0" xyz="0 0 -0.025" />
      <mass value="0.202000007" />
      <inertia ixx="0.000144345773151144" ixy="0" ixz="0" iyy="0.000144345773151144" iyz="0" izz="0.000204525000299327" />
    </inertial>
    <visual>
      <origin rpy="-4.712389 0 0" xyz="0 0 -0.1168" />
      <geometry>
        <mesh filename="package://meshes/wrist3.stl" scale="1 1 1" />
      </geometry>
      <material name="Aluminum">
        <color rgba="0.6981 0.6981 0.6981 1" />
      </material>
    </visual>
    <collision>
      <origin rpy="-4.712389 0 0" xyz="0 0 -0.1168" />
      <geometry>
        <mesh filename="package://meshes/wrist3.stl" scale="1 1 1" />
      </geometry>
    </collision>
  </link>
  <link name="flange" />
  <link name="tool0" />
  <joint name="base_link-base_link_inertia" type="fixed">
    <origin rpy="0 0 -3.141593" />
    <parent link="base" />
    <child link="base_link" />
  </joint>
  <joint name="shoulder_pan_joint" type="revolute">
    <origin xyz="0 0 0.1807" />
    <parent link="base_link" />
    <child link="shoulder_link" />
    <limit lower="-6.28318525850773" upper="6.28318525850773" effort="330" velocity="7" />
  </joint>
  <joint name="shoulder_lift_joint" type="revolute">
    <origin rpy="-4.712389 0 0" />
    <parent link="shoulder_link" />
    <child link="upper_arm_link" />
    <limit lower="-6.28318525850773" upper="6.28318525850773" effort="330" velocity="7" />
  </joint>
  <joint name="elbow_joint" type="revolute">
    <origin xyz="-0.6127 0 0" />
    <parent link="upper_arm_link" />
    <child link="forearm_link" />
    <limit lower="-3.14159262925386" upper="3.14159262925386" effort="150" velocity="7" />
  </joint>
  <joint name="wrist_1_joint" type="revolute">
    <origin xyz="-0.57155 0 0.17415" />
    <parent link="forearm_link" />
    <child link="wrist_1_link" />
    <limit lower="-6.28318525850773" upper="6.28318525850773" effort="56" velocity="7" />
  </joint>
  <joint name="wrist_2_joint" type="revolute">
    <origin rpy="-4.712389 0 0" xyz="0 -0.11985 0" />
    <parent link="wrist_1_link" />
    <child link="wrist_2_link" />
    <limit lower="-6.28318525850773" upper="6.28318525850773" effort="56" velocity="7" />
  </joint>
  <joint name="wrist_3_joint" type="revolute">
    <origin rpy="-1.570796 0 0" xyz="0 0.11655 0" />
    <parent link="wrist_2_link" />
    <child link="wrist_3_link" />
    <limit lower="-6.28318525850773" upper="6.28318525850773" effort="56" velocity="7" />
  </joint>
  <joint name="wrist_3-flange" type="fixed">
    <origin rpy="0 4.712389 -1.570796" />
    <parent link="wrist_3_link" />
    <child link="flange" />
  </joint>
  <joint name="flange-tool0" type="fixed">
    <origin rpy="-4.712389 0 -4.712389" />
    <parent link="flange" />
    <child link="tool0" />
  </joint>
</robot>